Workbook

Sheet P1
A1: validity | B1: targetSide | C1: cueDur_ms | D1: response_key.keys | E1: response_key.corr | F1: response_key.rt
H2: validity | I2: response_key.rt | K2: validity | L2: response_key.rt
A3: invalid | B3: left | C3: 150 | D3: z | E3: 1 | F3: 0.16488412
A4: invalid | B4: left | C4: 100 | D4: z | E4: 1 | F4: 0.40327333 | H4: invalid | I4: 0.16488412 | K4: valid | L4: 0.18694083
A5: invalid | B5: right | C5: 50 | D5: m | E5: 1 | F5: 0.40949554 | H5: invalid | I5: 0.40327333 | K5: valid | L5: 0.21561792 | O5: valid | P5: invalid
A6: invalid | B6: right | C6: 100 | D6: z | E6: 1 | F6: 0.14998887 | H6: invalid | I6: 0.40949554 | K6: valid | L6: 0.162984 | N6: acurracy | O6: =AVERAGE(E10:E50)*100 -> 100 | P6: =AVERAGE(E51:E98)*100 -> 95.833333
A7: invalid | B7: left | C7: 50 | D7: z | E7: 1 | F7: 0.33792567 | H7: invalid | I7: 0.14998887 | K7: valid | L7: 0.17617575
A8: invalid | B8: right | C8: 150 | D8: m | E8: 1 | F8: 0.34264333 | H8: invalid | I8: 0.33792567 | K8: valid | L8: 0.28585771
A9: invalid | B9: right | C9: 100 | D9: z | E9: 1 | F9: 0.37341229 | H9: invalid | I9: 0.34264333 | K9: valid | L9: 0.23170579
A10: invalid | B10: right | C10: 50 | D10: m | E10: 1 | F10: 0.30058375 | H10: invalid | I10: 0.37341229 | K10: valid | L10: 0.35026879
A11: invalid | B11: right | C11: 150 | D11: m | E11: 1 | F11: 0.30960087 | H11: invalid | I11: 0.30058375 | K11: valid | L11: 0.32809787
A12: invalid | B12: right | C12: 150 | D12: m | E12: 1 | F12: 0.068488083 | H12: invalid | I12: 0.30960087 | K12: valid | L12: 0.20430104
A13: invalid | B13: right | C13: 150 | D13: m | E13: 1 | F13: 0.061138292 | H13: invalid | I13: 0.068488083 | K13: valid | L13: 0.13616571
A14: invalid | B14: left | C14: 150 | D14: z | E14: 1 | F14: 0.11748958 | H14: invalid | I14: 0.061138292 | K14: valid | L14: 0.40582971
A15: invalid | B15: right | C15: 50 | D15: m | E15: 1 | F15: 0.15071029 | H15: invalid | I15: 0.11748958 | K15: valid | L15: 0.10156238
A16: invalid | B16: left | C16: 150 | D16: z | E16: 1 | F16: 0.095833666 | H16: invalid | I16: 0.15071029 | K16: valid | L16: 0.43618733
A17: invalid | B17: left | C17: 100 | D17: z | E17: 1 | F17: 0.18779967 | H17: invalid | I17: 0.095833666 | K17: valid | L17: 0.22571258
A18: invalid | B18: right | C18: 100 | D18: m | E18: 1 | F18: 0.15312158 | H18: invalid | I18: 0.18779967 | K18: valid | L18: 0.34744512
... A49: invalid | B49: left | C49: 50 | D49: z | E49: 1 | F49: 0.22996421 | H49: invalid | I49: 0.13159504 | K49: valid | L49: 0.13905788
A50: invalid | B50: right | C50: 150 | D50: m | E50: 1 | F50: 0.16386787 | H50: invalid | I50: 0.22996421
A51: valid | B51: left | C51: 50 | D51: z | E51: 1 | F51: 0.18694083 | H51: invalid | I51: 0.16386787
A52: valid | B52: right | C52: 50 | D52: m | E52: 1 | F52: 0.21561792 | H52: AVERAGE | I52: =AVERAGE(I4:I51) -> 0.2635427 | K52: AVERAGE | L52: =AVERAGE(L4:L49) -> 0.20720757
A53: valid | B53: right | C53: 100 | D53: m | E53: 1 | F53: 0.162984
A54: valid | B54: left | C54: 50 | D54: z | E54: 1 | F54: 0.17617575
E55: 0 | F55: 0.085687458 | H55: CUE | I55: VALID | J55: INVALID
A56: valid | B56: right | C56: 50 | D56: m | E56: 1 | F56: 0.28585771 | H56: 50 | I56: =AVERAGEIFS(F:F, A:A,"valid", C:C,50) -> 0.25472015 | J56: =AVERAGEIFS(F:F, A:A,"invalid", C:C,50) -> 0.31735602
A57: valid | B57: right | C57: 50 | D57: m | E57: 1 | F57: 0.23170579 | H57: 100 | I57: =AVERAGEIFS(F:F, A:A,"valid", C:C,100) -> 0.21761116 | J57: =AVERAGEIFS(F:F, A:A,"invalid", C:C,100) -> 0.31737216
A58: valid | B58: right | C58: 100 | D58: m | E58: 1 | F58: 0.35026879 | H58: 150 | I58: =AVERAGEIFS(F:F, A:A,"valid", C:C,150) -> 0.11338144 | J58: =AVERAGEIFS(F:F, A:A,"invalid", C:C,150) -> 0.18819276
A59: valid | B59: left | C59: 50 | D59: z | E59: 1 | F59: 0.32809787
A60: valid | B60: left | C60: 100 | D60: z | E60: 1 | F60: 0.20430104
A61: valid | B61: right | C61: 50 | D61: m | E61: 1 | F61: 0.13616571
A62: valid | B62: right | C62: 100 | D62: m | E62: 1 | F62: 0.40582971
A63: valid | B63: right | C63: 100 | D63: m | E63: 1 | F63: 0.10156238
A64: valid | B64: left | C64: 50 | D64: z | E64: 1 | F64: 0.43618733
A65: valid | B65: left | C65: 150 | D65: z | E65: 1 | F65: 0.22571258
A66: valid | B66: left | C66: 100 | D66: z | E66: 1 | F66: 0.34744512
A67: valid | B67: left | C67: 50 | D67: z | E67: 1 | F67: 0.25530729
A68: valid | B68: right | C68: 150 | D68: m | E68: 1 | F68: 0.2376745
A69: valid | B69: right | C69: 50 | D69: m | E69: 1 | F69: 0.40451213
A70: valid | B70: right | C70: 50 | D70: m | E70: 1 | F70: 0.44619008
...

Sheet P2
A1: validity | B1: targetSide | C1: cueDur_ms | D1: response_key.keys | E1: response_key.corr | F1: response_key.rt
I2: validity | J2: response_key.rt | L2: validity | M2: response_key.rt
A3: invalid | B3: left | C3: 50 | D3: z | E3: 1 | F3: 0.31221658
E4: 0 | I4: invalid | J4: 0.31221658 | L4: valid | M4: 0.32720683
A5: invalid | B5: right | C5: 50 | D5: m | E5: 1 | F5: 0.26571937 | I5: invalid | J5: 0.26571937 | L5: valid | M5: 0.10698025 | O5: valid | P5: invalid
A6: invalid | B6: right | C6: 150 | D6: m | E6: 1 | F6: 0.127638 | I6: invalid | J6: 0.127638 | L6: valid | M6: 0.21528567 | N6: acurracy | O6: =AVERAGE(E3:E50)*100 -> 97.916667 | P6: =AVERAGE(E51:E98)*100 -> 100
A7: invalid | B7: left | C7: 100 | D7: z | E7: 1 | F7: 0.15169692 | I7: invalid | J7: 0.15169692 | L7: valid | M7: 0.77629525
A8: invalid | B8: left | C8: 150 | D8: z | E8: 1 | F8: 0.103232 | I8: invalid | J8: 0.103232 | L8: valid | M8: 0.19597283
A9: invalid | B9: left | C9: 150 | D9: z | E9: 1 | F9: 0.10747842 | I9: invalid | J9: 0.10747842 | L9: valid | M9: 0.19870587
A10: invalid | B10: left | C10: 50 | D10: z | E10: 1 | F10: 0.23516846 | I10: invalid | J10: 0.23516846 | L10: valid | M10: 0.12401083
A11: invalid | B11: right | C11: 150 | D11: m | E11: 1 | F11: 0.12599204 | I11: invalid | J11: 0.12599204 | L11: valid | M11: 0.14411367
A12: invalid | B12: right | C12: 150 | D12: m | E12: 1 | F12: 0.14920108 | I12: invalid | J12: 0.14920108 | L12: valid | M12: 0.31774658
A13: invalid | B13: left | C13: 100 | D13: z | E13: 1 | F13: 0.21390887 | I13: invalid | J13: 0.21390887 | L13: valid | M13: 0.037326167
A14: invalid | B14: left | C14: 150 | D14: z | E14: 1 | F14: 0.08550325 | I14: invalid | J14: 0.08550325 | L14: valid | M14: 0.26374654
A15: invalid | B15: right | C15: 50 | D15: m | E15: 1 | F15: 0.21918979 | I15: invalid | J15: 0.21918979 | L15: valid | M15: 0.18350188
A16: invalid | B16: right | C16: 50 | D16: m | E16: 1 | F16: 0.1683105 | I16: invalid | J16: 0.1683105 | L16: valid | M16: 0.089196542
A17: invalid | B17: right | C17: 50 | D17: m | E17: 1 | F17: 0.20560712 | I17: invalid | J17: 0.20560712 | L17: valid | M17: 0.099675624
A18: invalid | B18: left | C18: 50 | D18: z | E18: 1 | F18: 0.25883937 | I18: invalid | J18: 0.25883937 | L18: valid | M18: 0.23302462
... A50: invalid | B50: right | C50: 150 | D50: m | E50: 1 | F50: 0.232273 | I50: invalid | J50: 0.232273 | L50: valid | M50: 0.19094092
A51: valid | B51: right | C51: 50 | D51: m | E51: 1 | F51: 0.32720683 | L51: valid | M51: 0.13011263
A52: valid | B52: right | C52: 150 | D52: m | E52: 1 | F52: 0.10698025 | I52: AVERAGE | J52: =AVERAGE(J4:J50) -> 0.20682954 | L52: AVERAGE | M52: =AVERAGE(M4:M51) -> 0.21587939
A53: valid | B53: right | C53: 50 | D53: m | E53: 1 | F53: 0.21528567
A54: valid | B54: left | C54: 100 | D54: z | E54: 1 | F54: 0.77629525 | H54: CUE | I54: VALID | J54: INVALID
A55: valid | B55: right | C55: 100 | D55: m | E55: 1 | F55: 0.19597283 | H55: 50 | I55: =AVERAGEIFS(F:F, A:A,"valid", C:C,50) -> 0.26282959 | J55: =AVERAGEIFS(F:F, A:A,"invalid", C:C,50) -> 0.25853812
A56: valid | B56: right | C56: 150 | D56: m | E56: 1 | F56: 0.19870587 | H56: 100 | I56: =AVERAGEIFS(F:F, A:A,"valid", C:C,100) -> 0.25710374 | J56: =AVERAGEIFS(F:F, A:A,"invalid", C:C,100) -> 0.22816243
A57: valid | B57: left | C57: 150 | D57: z | E57: 1 | F57: 0.12401083 | H57: 150 | I57: =AVERAGEIFS(F:F, A:A,"valid", C:C,150) -> 0.12806271 | J57: =AVERAGEIFS(F:F, A:A,"invalid", C:C,150) -> 0.13512138
A58: valid | B58: left | C58: 100 | D58: z | E58: 1 | F58: 0.14411367
A59: valid | B59: left | C59: 50 | D59: z | E59: 1 | F59: 0.31774658
A60: valid | B60: right | C60: 50 | D60: z | E60: 1 | F60: 0.037326167
A61: valid | B61: left | C61: 50 | D61: z | E61: 1 | F61: 0.26374654
A62: valid | B62: left | C62: 100 | D62: z | E62: 1 | F62: 0.18350188
A63: valid | B63: right | C63: 150 | D63: m | E63: 1 | F63: 0.089196542
A64: valid | B64: left | C64: 150 | D64: z | E64: 1 | F64: 0.099675624
A65: valid | B65: right | C65: 100 | D65: m | E65: 1 | F65: 0.23302462
A66: valid | B66: left | C66: 150 | D66: z | E66: 1 | F66: 0.145887
A67: valid | B67: left | C67: 100 | D67: z | E67: 1 | F67: 0.36807238
A68: valid | B68: right | C68: 100 | D68: m | E68: 1 | F68: 0.14729708
A69: valid | B69: left | C69: 100 | D69: z | E69: 1 | F69: 0.25037592
... A98: valid | B98: right | C98: 150 | D98: m | E98: 1 | F98: 0.13011263

Sheet P3
A1: validity | B1: targetSide | C1: cueDur_ms | D1: response_key.keys | E1: response_key.corr | F1: response_key.rt
I2: validity | J2: response_key.rt | L2: validity | M2: response_key.rt
A3: invalid | B3: left | C3: 150 | D3: z | E3: 1 | F3: 0.1416755
A4: invalid | B4: left | C4: 150 | D4: z | E4: 1 | F4: 0.094705874 | I4: invalid | J4: 0.1416755 | L4: valid | M4: 0.082622707
A5: invalid | B5: left | C5: 50 | D5: z | E5: 1 | F5: 0.16501008 | I5: invalid | J5: 0.094705874 | L5: valid | M5: 0.042080958 | P5: valid | Q5: invalid
A6: invalid | B6: left | C6: 100 | D6: z | E6: 1 | F6: 0.09702775 | I6: invalid | J6: 0.16501008 | L6: valid | M6: 0.051642791 | O6: acurracy | P6: =AVERAGE(E3:E50)*100 -> 100 | Q6: =AVERAGE(E51:E98)*100 -> 95.833333
A7: invalid | B7: left | C7: 50 | D7: z | E7: 1 | F7: 0.13112479 | I7: invalid | J7: 0.09702775 | L7: valid | M7: 0.046638458
A8: invalid | B8: left | C8: 100 | D8: z | E8: 1 | F8: 0.12342633 | I8: invalid | J8: 0.13112479 | L8: valid | M8: 0.13761567
A9: invalid | B9: left | C9: 50 | D9: z | E9: 1 | F9: 0.095856582 | I9: invalid | J9: 0.12342633 | L9: valid | M9: 0.027109458
A10: invalid | B10: left | C10: 100 | D10: z | E10: 1 | F10: 0.003120999 | I10: invalid | J10: 0.095856582 | L10: valid | M10: 0.082780333
A11: invalid | B11: left | C11: 100 | D11: z | E11: 1 | F11: 0.54762412 | I11: invalid | J11: 0.003120999 | L11: valid | M11: 0.44404204
A12: invalid | B12: left | C12: 50 | D12: z | E12: 1 | F12: 0.12719883 | I12: invalid | J12: 0.54762412 | L12: valid | M12: 0.21293017
A13: invalid | B13: left | C13: 50 | D13: z | E13: 1 | F13: 0.081060833 | I13: invalid | J13: 0.12719883 | L13: valid | M13: 0.082908249
A14: invalid | B14: left | C14: 150 | D14: z | E14: 1 | F14: 0.49627017 | I14: invalid | J14: 0.081060833 | L14: valid | M14: 0.17080937
A15: invalid | B15: right | C15: 50 | D15: m | E15: 1 | F15: 0.29458242 | I15: invalid | J15: 0.49627017 | L15: valid | M15: 0.16695896
A16: invalid | B16: right | C16: 50 | D16: m | E16: 1 | F16: 0.21689258 | I16: invalid | J16: 0.29458242 | L16: valid | M16: 0.099750291
A17: invalid | B17: right | C17: 100 | D17: m | E17: 1 | F17: 0.12780996 | I17: invalid | J17: 0.21689258 | L17: valid | M17: 0.052795291
A18: invalid | B18: left | C18: 150 | D18: z | E18: 1 | F18: 0.094410332 | I18: invalid | J18: 0.12780996 | L18: valid | M18: 0.26393096
... A49: invalid | B49: right | C49: 150 | D49: m | E49: 1 | F49: 0.004091957 | I49: invalid | J49: 0.083135791 | L49: valid | M49: 0.12738583
A50: invalid | B50: right | C50: 50 | D50: z | E50: 1 | F50: 0.068547041 | I50: invalid | J50: 0.004091957
A51: valid | B51: right | C51: 150 | D51: m | E51: 1 | F51: 0.082622707 | I51: invalid | J51: 0.068547041
A52: valid | B52: right | C52: 150 | D52: m | E52: 1 | F52: 0.042080958 | I52: AVERAGE | J52: =AVERAGE(J4:J51) -> 0.14149731 | L52: AVERAGE | M52: =AVERAGE(M4:M49) -> 0.13575413
A53: valid | B53: right | C53: 150 | D53: m | E53: 1 | F53: 0.051642791
A54: valid | B54: right | C54: 150 | D54: m | E54: 1 | F54: 0.046638458 | H54: CUE | I54: VALID | J54: INVALID
A55: valid | B55: right | C55: 50 | D55: m | E55: 1 | F55: 0.13761567 | H55: 50 | I55: =AVERAGEIFS(F:F, A:A,"valid", C:C,50) -> 0.18282273 | J55: =AVERAGEIFS(F:F, A:A,"invalid", C:C,50) -> 0.15442825
A56: valid | B56: right | C56: 150 | D56: m | E56: 1 | F56: 0.027109458 | H56: 100 | I56: =AVERAGEIFS(F:F, A:A,"valid", C:C,100) -> 0.15354677 | J56: =AVERAGEIFS(F:F, A:A,"invalid", C:C,100) -> 0.13129219
A57: valid | B57: right | C57: 100 | D57: m | E57: 1 | F57: 0.082780333 | H57: 150 | I57: =AVERAGEIFS(F:F, A:A,"valid", C:C,150) -> 0.084736595 | J57: =AVERAGEIFS(F:F, A:A,"invalid", C:C,150) -> 0.13618528
A58: valid | B58: right | C58: 100 | D58: m | E58: 1 | F58: 0.44404204
E59: 0
A60: valid | B60: left | C60: 50 | D60: z | E60: 1 | F60: 0.21293017
A61: valid | B61: left | C61: 100 | D61: z | E61: 1 | F61: 0.082908249
A62: valid | B62: right | C62: 50 | D62: m | E62: 1 | F62: 0.17080937
A63: valid | B63: left | C63: 150 | D63: z | E63: 1 | F63: 0.16695896
A64: valid | B64: left | C64: 150 | D64: z | E64: 1 | F64: 0.099750291
A65: valid | B65: right | C65: 150 | D65: m | E65: 1 | F65: 0.052795291
A66: valid | B66: left | C66: 50 | D66: z | E66: 1 | F66: 0.26393096
A67: valid | B67: right | C67: 100 | D67: m | E67: 1 | F67: 0.16982417
A68: valid | B68: left | C68: 50 | D68: z | E68: 1 | F68: 0.16254742
A69: valid | B69: right | C69: 150 | D69: m | E69: 1 | F69: 0.079049083
A70: valid | B70: right | C70: 100 | D70: m | E70: 1 | F70: 0.16656204
...

Sheet P4
A1: validity | B1: targetSide | C1: cueDur_ms | D1: response_key.keys | E1: response_key.corr | F1: response_key.rt
I2: validity | J2: response_key.rt | L2: validity | M2: response_key.rt
A3: invalid | B3: right | C3: 150 | D3: m | E3: 1 | F3: 0.12186146
A4: invalid | B4: left | C4: 150 | D4: z | E4: 1 | F4: 0.11255625 | I4: invalid | J4: 0.12186146 | L4: valid | M4: 0.22229683
A5: invalid | B5: left | C5: 150 | D5: z | E5: 1 | F5: 0.099244083 | I5: invalid | J5: 0.11255625 | L5: valid | M5: 0.18264 | O5: valid | P5: invalid
A6: invalid | B6: right | C6: 50 | D6: m | E6: 1 | F6: 0.24629525 | I6: invalid | J6: 0.099244083 | L6: valid | M6: 0.21021237 | N6: acurracy | O6: =AVERAGE(E3:E50)*100 -> 100 | P6: =AVERAGE(E51:E98)*100 -> 100
A7: invalid | B7: left | C7: 100 | D7: z | E7: 1 | F7: 0.12041817 | I7: invalid | J7: 0.24629525 | L7: valid | M7: 0.21655862
A8: invalid | B8: right | C8: 100 | D8: z | E8: 1 | F8: 0.15935246 | I8: invalid | J8: 0.12041817 | L8: valid | M8: 0.18968379
A9: invalid | B9: right | C9: 50 | D9: m | E9: 1 | F9: 0.3657545 | I9: invalid | J9: 0.15935246 | L9: valid | M9: 0.11305854
A10: invalid | B10: left | C10: 50 | D10: z | E10: 1 | F10: 0.33376542 | I10: invalid | J10: 0.3657545 | L10: valid | M10: 0.15528687
A11: invalid | B11: left | C11: 150 | D11: z | E11: 1 | F11: 0.29738171 | I11: invalid | J11: 0.33376542 | L11: valid | M11: 0.116132
A12: invalid | B12: right | C12: 150 | D12: m | E12: 1 | F12: 0.27036438 | I12: invalid | J12: 0.29738171 | L12: valid | M12: 0.14839154
A13: invalid | B13: right | C13: 150 | D13: m | E13: 1 | F13: 0.2058625 | I13: invalid | J13: 0.27036438 | L13: valid | M13: 0.17933625
A14: invalid | B14: right | C14: 50 | D14: m | E14: 1 | F14: 0.22010271 | I14: invalid | J14: 0.2058625 | L14: valid | M14: 0.19008929
A15: invalid | B15: left | C15: 50 | D15: z | E15: 1 | F15: 0.232063 | I15: invalid | J15: 0.22010271 | L15: valid | M15: 0.18208858
A16: invalid | B16: left | C16: 100 | D16: z | E16: 1 | F16: 0.22438742 | I16: invalid | J16: 0.232063 | L16: valid | M16: 0.12976038
A17: invalid | B17: right | C17: 50 | D17: m | E17: 1 | F17: 0.24728279 | I17: invalid | J17: 0.22438742 | L17: valid | M17: 0.15239883
A18: invalid | B18: right | C18: 100 | D18: m | E18: 1 | F18: 0.24895317 | I18: invalid | J18: 0.24728279 | L18: valid | M18: 0.21952583
... A51: valid | B51: left | C51: 50 | D51: z | E51: 1 | F51: 0.22229683 | I51: invalid | J51: 0.15197446 | L51: valid | M51: 0.18294546
A52: valid | B52: left | C52: 50 | D52: z | E52: 1 | F52: 0.18264 | I52: AVERAGE | J52: =AVERAGE(J4:J51) -> 0.1767255 | L52: AVERAGE | M52: =AVERAGE(M4:M51) -> 0.15401257
A53: valid | B53: left | C53: 50 | D53: z | E53: 1 | F53: 0.21021237
A54: valid | B54: right | C54: 50 | D54: m | E54: 1 | F54: 0.21655862 | H54: CUE | I54: VALID | J54: INVALID
A55: valid | B55: left | C55: 50 | D55: z | E55: 1 | F55: 0.18968379 | H55: 50 | I55: =AVERAGEIFS(F:F, A:A,"valid", C:C,50) -> 0.19518394 | J55: =AVERAGEIFS(F:F, A:A,"invalid", C:C,50) -> 0.23922829
A56: valid | B56: right | C56: 150 | D56: m | E56: 1 | F56: 0.11305854 | H56: 100 | I56: =AVERAGEIFS(F:F, A:A,"valid", C:C,100) -> 0.13805333 | J56: =AVERAGEIFS(F:F, A:A,"invalid", C:C,100) -> 0.16906585
A57: valid | B57: left | C57: 50 | D57: z | E57: 1 | F57: 0.15528687 | H57: 150 | I57: =AVERAGEIFS(F:F, A:A,"valid", C:C,150) -> 0.098626129 | J57: =AVERAGEIFS(F:F, A:A,"invalid", C:C,150) -> 0.14982186
A58: valid | B58: right | C58: 100 | D58: m | E58: 1 | F58: 0.116132
A59: valid | B59: right | C59: 150 | D59: m | E59: 1 | F59: 0.14839154
A60: valid | B60: right | C60: 50 | D60: m | E60: 1 | F60: 0.17933625
A61: valid | B61: left | C61: 100 | D61: z | E61: 1 | F61: 0.19008929
A62: valid | B62: left | C62: 50 | D62: z | E62: 1 | F62: 0.18208858
A63: valid | B63: left | C63: 100 | D63: z | E63: 1 | F63: 0.12976038
A64: valid | B64: left | C64: 50 | D64: z | E64: 1 | F64: 0.15239883
A65: valid | B65: right | C65: 50 | D65: m | E65: 1 | F65: 0.21952583
A66: valid | B66: right | C66: 150 | D66: m | E66: 1 | F66: 0.09808225
A67: valid | B67: left | C67: 100 | D67: z | E67: 1 | F67: 0.099059166
A68: valid | B68: left | C68: 150 | D68: z | E68: 1 | F68: 0.10074408
A69: valid | B69: right | C69: 50 | D69: m | E69: 1 | F69: 0.19811821
... A98: valid | B98: right | C98: 50 | D98: m | E98: 1 | F98: 0.18294546

Sheet P5
A1: validity | B1: targetSide | C1: cueDur_ms | D1: response_key.keys | E1: response_key.corr | F1: response_key.rt
I2: validity | J2: response_key.rt | L2: validity | M2: response_key.rt
A3: invalid | B3: left | C3: 50 | D3: z | E3: 1 | F3: 2.0561291
A4: invalid | B4: right | C4: 50 | D4: m | E4: 1 | F4: 1.5129275 | I4: invalid | J4: 2.0561291 | L4: valid | M4: 0.63324
A5: invalid | B5: left | C5: 100 | D5: z | E5: 1 | F5: 1.3816472 | I5: invalid | J5: 1.5129275 | L5: valid | M5: 0.55367142 | O5: valid | P5: invalid
A6: invalid | B6: left | C6: 100 | D6: z | E6: 1 | F6: 1.5580026 | I6: invalid | J6: 1.3816472 | L6: valid | M6: 0.47831221 | N6: acurracy | O6: =AVERAGE(E3:E50)*100 -> 100 | P6: =AVERAGE(E51:E98)*100 -> 97.916667
A7: invalid | B7: right | C7: 100 | D7: m | E7: 1 | F7: 0.62394879 | I7: invalid | J7: 1.5580026 | L7: valid | M7: 0.62163483
A8: invalid | B8: left | C8: 100 | D8: z | E8: 1 | F8: 0.66774104 | I8: invalid | J8: 0.62394879 | L8: valid | M8: 0.69059396
A9: invalid | B9: right | C9: 150 | D9: m | E9: 1 | F9: 0.82343683 | I9: invalid | J9: 0.66774104 | L9: valid | M9: 0.63723483
A10: invalid | B10: left | C10: 50 | D10: z | E10: 1 | F10: 1.2896684 | I10: invalid | J10: 0.82343683 | L10: valid | M10: 0.56894929
A11: invalid | B11: left | C11: 150 | D11: z | E11: 1 | F11: 0.5485795 | I11: invalid | J11: 1.2896684 | L11: valid | M11: 0.62520108
A12: invalid | B12: left | C12: 150 | D12: z | E12: 1 | F12: 0.43734783 | I12: invalid | J12: 0.5485795 | L12: valid | M12: 0.52791117
A13: invalid | B13: left | C13: 150 | D13: z | E13: 1 | F13: 1.1062273 | I13: invalid | J13: 0.43734783 | L13: valid | M13: 0.29769688
A14: invalid | B14: left | C14: 150 | D14: z | E14: 1 | F14: 1.771088 | I14: invalid | J14: 1.1062273 | L14: valid | M14: 0.19243742
A15: invalid | B15: left | C15: 100 | D15: z | E15: 1 | F15: 1.6117591 | I15: invalid | J15: 1.771088 | L15: valid | M15: 0.20877417
A16: invalid | B16: right | C16: 150 | D16: m | E16: 1 | F16: 0.40389629 | I16: invalid | J16: 1.6117591 | L16: valid | M16: 0.50300079
A17: invalid | B17: right | C17: 50 | D17: m | E17: 1 | F17: 0.53283412 | I17: invalid | J17: 0.40389629 | L17: valid | M17: 0.83610175
A18: invalid | B18: left | C18: 50 | D18: z | E18: 1 | F18: 0.779178 | I18: invalid | J18: 0.53283412 | L18: valid | M18: 0.31478475
... A50: invalid | B50: left | C50: 50 | D50: z | E50: 1 | F50: 0.721908 | I50: invalid | J50: 1.0451652 | L50: valid | M50: 1.1154262
E51: 0 | I51: invalid | J51: 0.721908
A52: valid | B52: left | C52: 100 | D52: z | E52: 1 | F52: 0.63324 | I52: AERAGE | J52: =AVERAGE(J4:J51) -> 0.97715971 | L52: AVERAGE | M52: =AVERAGE(M4:M50) -> 0.83624535
A53: valid | B53: right | C53: 100 | D53: m | E53: 1 | F53: 0.55367142
A54: valid | B54: left | C54: 150 | D54: z | E54: 1 | F54: 0.47831221 | H54: CUE | I54: VALID | J54: INVALID
A55: valid | B55: left | C55: 100 | D55: z | E55: 1 | F55: 0.62163483 | H55: 50 | I55: =AVERAGEIFS(F:F, A:A,"valid", C:C,50) -> 0.97716736 | J55: =AVERAGEIFS(F:F, A:A,"invalid", C:C,50) -> 1.1203518
A56: valid | B56: right | C56: 150 | D56: m | E56: 1 | F56: 0.69059396 | H56: 100 | I56: =AVERAGEIFS(F:F, A:A,"valid", C:C,100) -> 0.90642605 | J56: =AVERAGEIFS(F:F, A:A,"invalid", C:C,100) -> 0.90279961
A57: valid | B57: right | C57: 100 | D57: m | E57: 1 | F57: 0.63723483 | H57: 150 | I57: =AVERAGEIFS(F:F, A:A,"valid", C:C,150) -> 0.60635302 | J57: =AVERAGEIFS(F:F, A:A,"invalid", C:C,150) -> 0.92079975
A58: valid | B58: right | C58: 150 | D58: m | E58: 1 | F58: 0.56894929
A59: valid | B59: left | C59: 50 | D59: z | E59: 1 | F59: 0.62520108
A60: valid | B60: right | C60: 50 | D60: m | E60: 1 | F60: 0.52791117
A61: valid | B61: left | C61: 50 | D61: z | E61: 1 | F61: 0.29769688
A62: valid | B62: right | C62: 150 | D62: m | E62: 1 | F62: 0.19243742
A63: valid | B63: left | C63: 150 | D63: z | E63: 1 | F63: 0.20877417
A64: valid | B64: left | C64: 100 | D64: z | E64: 1 | F64: 0.50300079
A65: valid | B65: left | C65: 100 | D65: z | E65: 1 | F65: 0.83610175
A66: valid | B66: right | C66: 150 | D66: m | E66: 1 | F66: 0.31478475
A67: valid | B67: right | C67: 150 | D67: z | E67: 1 | F67: 0.66016971
A68: valid | B68: left | C68: 50 | D68: z | E68: 1 | F68: 1.444535
A69: valid | B69: right | C69: 50 | D69: m | E69: 1 | F69: 0.72539121
... A98: valid | B98: right | C98: 50 | D98: m | E98: 1 | F98: 1.1154262

Sheet Analysis
B1: PARTICIPANT | C1: INVALID | D1: VALID | F1: PARTICIPANT | G1: V_50 | H1: V_100 | I1: V_150 | J1: I_50 | K1: I_100 | L1: I_150
A2: AVERAGE | B2: 1 | C2: =AVERAGE('P1'!I4:I51) -> 0.2635427 | D2: =AVERAGE('P1'!L4:L49) -> 0.20720757 | F2: 1 | G2: 0.25472015 | H2: 0.21761116 | I2: 0.11338144 | J2: 0.31735602 | K2: 0.31737216 | L2: 0.18819276
A3: AVERAGE | B3: 2 | C3: =AVERAGE('P2'!J4:J50) -> 0.20682954 | D3: =AVERAGE('P2'!M4:M51) -> 0.21587939 | F3: 2 | G3: 0.26282959 | H3: 0.25710374 | I3: 0.12806271 | J3: 0.25853812 | K3: 0.22816243 | L3: 0.13512138
A4: AVERAGE | B4: 3 | C4: =AVERAGE('P3'!J4:J51) -> 0.14149731 | D4: =AVERAGE('P3'!M4:M49) -> 0.13575413 | F4: 3 | G4: 0.18282273 | H4: 0.15354677 | I4: 0.084736595 | J4: 0.15442825 | K4: 0.13129219 | L4: 0.13618528
A5: AVERAGE | B5: 4 | C5: =AVERAGE('P4'!J4:J51) -> 0.1767255 | D5: =AVERAGE('P4'!M4:M51) -> 0.15401257 | F5: 4 | G5: 0.19518394 | H5: 0.13805333 | I5: 0.098626129 | J5: 0.23922829 | K5: 0.16906585 | L5: 0.14982186
A6: AVERAGE | B6: 5 | C6: =AVERAGE('P5'!J4:J51) -> 0.97715971 | D6: =AVERAGE('P5'!M4:M50) -> 0.83624535 | F6: 5 | G6: 0.97716736 | H6: 0.90642605 | I6: 0.60635302 | J6: 1.1203518 | K6: 0.90279961 | L6: 0.92079975
A7: AVERAGE | C7: =AVERAGE(C2:C6) -> 0.35315095 | D7: =AVERAGE(D2:D6) -> 0.3098198 | F7: AVERAGE | G7: =AVERAGE(G2:G6) -> 0.37454476 | H7: =AVERAGE(H2:H6) -> 0.33454821 | I7: =AVERAGE(I2:I6) -> 0.20623198 | J7: =AVERAGE(J2:J6) -> 0.41798049 | K7: =AVERAGE(K2:K6) -> 0.34973845 | L7: =AVERAGE(L2:L6) -> 0.30602421
B8: P1
A9: CUE | B9: VALID | C9: INVALID
A10: 50 | B10: 0.25472015 | C10: 0.31735602 | F10: PARTICIPANT | G10: ACCURACY | J10: PARTICIPANT | K10: VALID | L10: INVALID
A11: 100 | B11: 0.21761116 | C11: 0.31737216 | F11: 1 | G11: =94/96*100 -> 97.916667 | J11: 1 | K11: 100 | L11: 95.833333
A12: 150 | B12: 0.11338144 | C12: 0.18819276 | F12: 2 | G12: =95/96*100 -> 98.958333 | J12: 2 | K12: 97.916667 | L12: 100
F13: 3 | G13: =94/96*100 -> 97.916667 | J13: 3 | K13: 100 | L13: 95.833333
B14: P2 | F14: 4 | G14: =96/96*100 -> 100 | J14: 4 | K14: 100 | L14: 100
A15: CUE | B15: VALID | C15: INVALID | F15: 5 | G15: =94/96*100 -> 97.916667 | J15: 5 | K15: 100 | L15: 97.916667
A16: 50 | B16: 0.26282959 | C16: 0.25853812
A17: 100 | B17: 0.25710374 | C17: 0.22816243
A18: 150 | B18: 0.12806271 | C18: 0.13512138
B20: P3
A21: CUE | B21: VALID | C21: INVALID
A22: 50 | B22: 0.18282273 | C22: 0.15442825
A23: 100 | B23: 0.15354677 | C23: 0.13129219
A24: 150 | B24: 0.084736595 | C24: 0.13618528
B26: P4
A27: CUE | B27: VALID | C27: INVALID
A28: 50 | B28: 0.19518394 | C28: 0.23922829
A29: 100 | B29: 0.13805333 | C29: 0.16906585
A30: 150 | B30: 0.098626129 | C30: 0.14982186
B32: P5
A33: CUE | B33: VALID | C33: INVALID
A34: 50 | B34: 0.97716736 | C34: 1.1203518
A35: 100 | B35: 0.90642605 | C35: 0.90279961
A36: 150 | B36: 0.60635302 | C36: 0.92079975
