Workbook

Sheet Participant 1
A1: Participant 1 | E1: Participant 1
A3: mouse.time | B3: mouse.clicked_name | C3: num_distr | E3: Size 5 RT | F3: Size 10 RT
A4: 3.7776122 | B4: None | C4: 10 | E4: 1.8040447 | F4: 5.2440662
A5: 5.2440662 | B5: target' | C5: 10 | E5: 1.6841071 | F5: 1.9881513
A6: 1.8040447 | B6: target' | C6: 5 | E6: 1.9212152 | F6: 1.8877015
A7: 1.6841071 | B7: target' | C7: 5 | E7: 1.5408117 | F7: 2.9191773
A8: 1.9881513 | B8: target' | C8: 10 | E8: 2.2339089 | F8: 1.3515614
A9: 1.9212152 | B9: target' | C9: 5 | E9: 2.1678123 | F9: 1.5562474
A10: 1.8877015 | B10: target' | C10: 10 | E10: 1.9494226 | F10: 3.3508106
A11: 1.5408117 | B11: target' | C11: 5 | E11: 1.648459 | F11: 3.0201796
A12: 2.2339089 | B12: target' | C12: 5 | E12: 2.4046542 | F12: 1.3087728
A13: 2.1678123 | B13: target' | C13: 5 | E13: 1.6560016 | F13: 3.4358425
A14: 1.9494226 | B14: target' | C14: 5 | E14: 1.9052545 | F14: 1.6197339
A15: 1.648459 | B15: target' | C15: 5 | E15: 2.1505279 | F15: 1.79502
... A100: 1.305616 | B100: target' | C100: 10 | E100: 1.6557056 | F100: 1.2434955
A101: 1.3979145 | B101: target' | C101: 10 | E101: 1.3869185
A102: 1.2118849 | B102: target' | C102: 10 | E102: 2.2400032
A103: 2.1884815 | B103: target' | C103: 5 | E103: 2.0473119
A104: 1.6012852 | B104: target' | C104: 5
A105: 1.1339405 | B105: target' | C105: 5
A106: 1.2849162 | B106: target' | C106: 5
A107: 1.5848423 | B107: target' | C107: 5 | E107: Mean
A108: 1.4207224 | B108: target' | C108: 10
A109: 1.8808294 | B109: target' | C109: 10 | E109: =AVERAGE(E4:E103) -> 1.7407991 | F109: =AVERAGE(F4:F105) -> 1.7959258
A110: 1.8722692 | B110: target' | C110: 5
A111: 1.452111 | B111: target' | C111: 5
A112: 1.4872509 | B112: target' | C112: 10
A113: 1.9623568 | B113: target' | C113: 10
A114: 1.9609407 | B114: target' | C114: 10
A115: 1.9266535 | B115: target' | C115: 5
A116: 1.6125525 | B116: target' | C116: 5
A117: 1.6349723 | B117: target' | C117: 5
A118: 1.7847061 | B118: target' | C118: 5
A119: 1.3061806 | B119: target' | C119: 10
A120: 2.0790823 | B120: target' | C120: 10
A121: 1.7454379 | B121: target' | C121: 10
... A203: 1.2434955 | B203: target' | C203: 10

Sheet Participant 2
A1: Participant 2 | E1: Participant 2
A3: mouse.time | B3: mouse.clicked_name | C3: num_distr | E3: Size 5 RT | F3: Size 10 RT
A4: 2.2527392 | B4: target' | C4: 5 | E4: 2.2527392 | F4: 1.535992
A5: 1.7638596 | B5: target' | C5: 5 | E5: 1.7638596 | F5: 1.6300803
A6: 1.535992 | B6: target' | C6: 10 | E6: 2.3864675 | F6: 1.5080698
A7: 1.6300803 | B7: target' | C7: 10 | E7: 1.8503547 | F7: 1.752737
A8: 2.3864675 | B8: target' | C8: 5 | E8: 1.7673019 | F8: 1.6222667
A9: 1.8503547 | B9: target' | C9: 5 | E9: 1.9260875 | F9: 1.8381952
A10: 1.7673019 | B10: target' | C10: 5 | E10: 1.9237216 | F10: 1.4452509
A11: 1.9260875 | B11: target' | C11: 5 | E11: 1.6728454 | F11: 2.8722991
A12: 1.5080698 | B12: target' | C12: 10 | E12: 1.7824 | F12: 2.6709282
A13: 1.9237216 | B13: target' | C13: 5 | E13: 1.9904471 | F13: 1.5541411
A14: 1.752737 | B14: target' | C14: 10 | E14: 1.6737669 | F14: 1.4535188
A15: 1.6728454 | B15: target' | C15: 5 | E15: 1.4009175 | F15: 1.521079
... A98: 1.5962945 | B98: target' | C98: 10 | E98: 1.4046567 | F98: 2.5255267
A99: 2.0777835 | B99: target' | C99: 10
A100: 1.9464452 | B100: target' | C100: 10 | F100: 1.8239355
A101: 1.2439932 | B101: target' | C101: 10 | F101: 1.7784223
A102: 1.5107874 | B102: target' | C102: 10 | F102: 2.6392016
A103: 1.1561947 | B103: target' | C103: 5 | F103: 1.6365325
A104: 2.3508731 | B104: target' | C104: 5 | F104: 2.4561375
A105: 1.7516077 | B105: target' | C105: 5 | F105: 1.3384287
A106: 2.0693231 | B106: target' | C106: 10 | F106: 1.2216743
A107: 1.4309556 | B107: target' | C107: 10 | F107: 1.313025
A108: 1.4548345 | B108: target' | C108: 5 | F108: 2.1626806
A109: 1.1884419 | B109: target' | C109: 10 | F109: 1.5450698
A110: 1.2891883 | B110: target' | C110: 5
A111: 1.6326396 | B111: target' | C111: 5 | E111: Mean
A112: 2.1220761 | B112: target' | C112: 10
A113: 1.5370567 | B113: target' | C113: 5 | E113: =AVERAGE(E4:E98) -> 1.7542999 | F113: =AVERAGE(F4:F109) -> 1.8368055
A114: 2.4908414 | B114: target' | C114: 10
A115: 1.640704 | B115: target' | C115: 5
A116: 2.4861413 | B116: target' | C116: 10
A117: 1.4392271 | B117: target' | C117: 5
A118: 2.5046849 | B118: target' | C118: 10
A119: 2.0775379 | B119: target' | C119: 10
A120: 1.3382328 | B120: target' | C120: 5
A121: 1.5734361 | B121: target' | C121: 10
A122: 2.393827 | B122: target' | C122: 10
A123: 1.5284674 | B123: target' | C123: 5
...

Sheet Participant 3
A1: Participant 3 | E1: Participant 3
A3: mouse.time | B3: mouse.clicked_name | C3: num_distr | E3: Size 5 RT | F3: Size 10 RT
A4: 2.6581278 | B4: target' | C4: 10 | E4: 1.6656696 | F4: 2.6581278
A5: 1.9831893 | B5: target' | C5: 10 | E5: 1.3842627 | F5: 1.9831893
A6: 1.6656696 | B6: target' | C6: 5 | E6: 2.0719368 | F6: 1.3693808
A7: 1.3842627 | B7: target' | C7: 5 | E7: 1.8902868 | F7: 3.9726299
A8: 1.3693808 | B8: target' | C8: 10 | E8: 2.2062858 | F8: 1.39193
A9: 2.0719368 | B9: target' | C9: 5 | E9: 1.921702 | F9: 1.435232
A10: 3.9726299 | B10: target' | C10: 10 | E10: 2.4006226 | F10: 1.7849508
A11: 1.39193 | B11: target' | C11: 10 | E11: 2.4223625 | F11: 2.628523
A12: 1.8902868 | B12: target' | C12: 5 | E12: 1.268326 | F12: 2.4553279
A13: 1.435232 | B13: target' | C13: 10 | E13: 3.2480704 | F13: 1.028215
A14: 2.2062858 | B14: target' | C14: 5 | E14: 2.7561455 | F14: 2.0775659
A15: 1.7849508 | B15: target' | C15: 10 | E15: 1.7833739 | F15: 2.9216292
... A101: 1.8606983 | B101: target' | C101: 10 | E101: 1.5698205 | F101: 1.5356517
A102: 2.7399513 | B102: target' | C102: 5 | E102: 1.3667869
A103: 1.9312385 | B103: target' | C103: 5
A104: 1.9337425 | B104: target' | C104: 5
A105: 1.6331392 | B105: target' | C105: 5
A106: 2.936885 | B106: target' | C106: 10
A107: 1.4056162 | B107: target' | C107: 5
A108: 2.0854343 | B108: target' | C108: 10 | E108: Mean
A109: 3.1115531 | B109: target' | C109: 10
A110: 2.2127258 | B110: target' | C110: 10 | E110: =AVERAGE(E4:E102) -> 1.9191755 | F110: =AVERAGE(F4:F101) -> 2.1797019
A111: 2.5081763 | B111: target' | C111: 10
A112: 1.5736392 | B112: target' | C112: 5
A113: 2.0860897 | B113: target' | C113: 10
A114: 2.2278001 | B114: target' | C114: 10
A115: 3.1131792 | B115: target' | C115: 10
A116: 1.9948398 | B116: target' | C116: 10
A117: 1.3044985 | B117: target' | C117: 5
A118: 2.9210049 | B118: target' | C118: 10
A119: 2.1067545 | B119: target' | C119: 5
A120: 3.5192159 | B120: target' | C120: 10
A121: 2.1886583 | B121: target' | C121: 5
A122: 2.8212798 | B122: target' | C122: 10
... A203: 1.5356517 | B203: target' | C203: 10

Sheet Participant 4
A1: Participant 4 | E1: Participant 4
A3: mouse.time | B3: mouse.clicked_name | C3: num_distr | E3: Size 5 RT | F3: Size 10 RT
A4: 2.8430977 | B4: target' | C4: 5 | E4: 2.8430977 | F4: 3.0525297
A5: 3.7669126 | B5: target' | C5: 5 | E5: 3.7669126 | F5: 3.7698787
A6: 2.6811219 | B6: target' | C6: 5 | E6: 2.6811219 | F6: 1.8948857
A7: 3.0525297 | B7: target' | C7: 10 | E7: 2.5054467 | F7: 2.9875453
A8: 2.5054467 | B8: target' | C8: 5 | E8: 2.2525539 | F8: 2.0712801
A9: 2.2525539 | B9: target' | C9: 5 | E9: 1.9219107 | F9: 2.0851698
A10: 2.1674833 | B10: None | C10: 10 | E10: 2.2896465 | F10: 3.9743326
A11: 1.9219107 | B11: target' | C11: 5 | E11: 2.3722998 | F11: 2.521091
A12: 3.7698787 | B12: target' | C12: 10 | E12: 1.5385707 | F12: 2.444476
A13: 1.8948857 | B13: target' | C13: 10 | E13: 2.2731061 | F13: 2.3559275
A14: 2.2896465 | B14: target' | C14: 5 | E14: 2.4168566 | F14: 2.0390811
A15: 2.9875453 | B15: target' | C15: 10 | E15: 2.2826713 | F15: 2.0021981
... A92: 2.685438 | B92: target' | C92: 10 | E92: 2.2870088 | F92: 3.3857429
A93: 2.5226345 | B93: target' | C93: 5 | E93: 3.1379935
A94: 3.667604 | B94: target' | C94: 5 | E94: 2.1226002
A95: 2.9637325 | B95: target' | C95: 5 | E95: 2.1549238
A96: 2.8914034 | B96: target' | C96: 5 | E96: 1.9665175
A97: 2.0208351 | B97: target' | C97: 10 | E97: 3.8387352
A98: 3.2053498 | B98: target' | C98: 5 | E98: 6.13695
A99: 2.967717 | B99: target' | C99: 5 | E99: 2.5301677
A100: 2.9333481 | B100: target' | C100: 5 | E100: 2.5000688
A101: 2.0849006 | B101: target' | C101: 5 | E101: 1.6215029
A102: 4.0875323 | B102: target' | C102: 10 | E102: 4.3430968
A103: 2.3118897 | B103: target' | C103: 10 | E103: 1.9396569
A104: 2.2200765 | B104: target' | C104: 5 | E104: 2.987103
... A111: 2.0576809 | B111: target' | C111: 10 | E111: 2.6058501
A112: 2.3214308 | B112: target' | C112: 5
A113: 2.7366306 | B113: target' | C113: 10
A114: 3.7716266 | B114: target' | C114: 5
A115: 2.119413 | B115: target' | C115: 10
A116: 2.4269398 | B116: target' | C116: 10 | E116: Mean
A117: 2.9282485 | B117: target' | C117: 10
A118: 2.9967553 | B118: target' | C118: 10 | E118: =AVERAGE(E4:E111) -> 2.6574934 | F118: =AVERAGE(F4:F114) -> 2.8666971
A119: 2.11696 | B119: target' | C119: 10
A120: 3.4552381 | B120: target' | C120: 5
A121: 2.5221173 | B121: target' | C121: 10
A122: 3.8226727 | B122: target' | C122: 5
A123: 3.421121 | B123: target' | C123: 10
...

Sheet Participant 5
A1: Participant 5 | E1: Participant 5
A3: mouse.time | B3: mouse.clicked_name | C3: num_distr | E3: Size 5 RT | F3: Size 10 RT
A4: 3.502306 | B4: target' | C4: 10 | E4: 3.0685002 | F4: 3.502306
A5: 2.8244537 | B5: target' | C5: 10 | E5: 3.2239554 | F5: 2.8244537
A6: 2.0960459 | B6: target' | C6: 10 | E6: 1.430917 | F6: 2.0960459
A7: 3.0685002 | B7: target' | C7: 5 | E7: 1.9997166 | F7: 3.2222294
A8: 3.2222294 | B8: target' | C8: 10 | E8: 2.9708293 | F8: 2.9681207
A9: 3.2239554 | B9: target' | C9: 5 | E9: 2.8835574 | F9: 3.1532151
A10: 1.430917 | B10: target' | C10: 5 | E10: 2.9979605 | F10: 1.5708566
A11: 1.9997166 | B11: target' | C11: 5 | E11: 2.9334009 | F11: 1.989282
A12: 2.9681207 | B12: target' | C12: 10 | E12: 3.2991702 | F12: 3.3424916
A13: 2.9708293 | B13: target' | C13: 5 | E13: 3.369779 | F13: 2.7096045
A14: 2.8835574 | B14: target' | C14: 5 | E14: 2.1486735 | F14: 2.12685
A15: 2.9979605 | B15: target' | C15: 5 | E15: 2.7705006 | F15: 3.1787533
... A102: 3.0189263 | B102: target' | C102: 10 | E102: 3.7828331 | F102: 3.1447013
A103: 2.6722203 | B103: target' | C103: 5 | E103: 3.1872058
A104: 5.2998412 | B104: target' | C104: 5
A105: 2.2696404 | B105: target' | C105: 10
A106: 3.237957 | B106: target' | C106: 5 | E106: Mean
A107: 2.3167817 | B107: target' | C107: 5
A108: 3.1034213 | B108: target' | C108: 10 | E108: =AVERAGE(E4:E103) -> 2.7841589 | F108: =AVERAGE(F4:F102) -> 2.9211542
A109: 2.1048386 | B109: target' | C109: 5
A110: 2.9333177 | B110: target' | C110: 5
A111: 4.6030647 | B111: target' | C111: 10
A112: 2.6885101 | B112: target' | C112: 5
A113: 2.9565885 | B113: target' | C113: 10
A114: 2.7042157 | B114: target' | C114: 5
A115: 2.952301 | B115: target' | C115: 10
A116: 2.5894522 | B116: target' | C116: 5
A117: 2.180687 | B117: target' | C117: 5
A118: 2.0997391 | B118: target' | C118: 5
A119: 2.0521671 | B119: target' | C119: 10
A120: 1.8442249 | B120: target' | C120: 10
... A203: 3.1447013 | B203: target' | C203: 10

Sheet Results
A2: Participant Number | B2: Set Size 5 Mean RT | C2: Set Size 10 Mean RT | D2: Slope | F2: Difference in Set Size = | G2: 5
A3: 1 | B3: ='Participant 1'!E109 -> 1.7407991 | C3: ='Participant 1'!F109 -> 1.7959258 | D3: =(C3-B3)/$G$2 -> 0.011025336
A4: 2 | B4: ='Participant 2'!E113 -> 1.7542999 | C4: ='Participant 2'!F113 -> 1.8368055 | D4: =(C4-B4)/$G$2 -> 0.016501118
A5: 3 | B5: ='Participant 3'!E110 -> 1.9191755 | C5: ='Participant 3'!F110 -> 2.1797019 | D5: =(C5-B5)/$G$2 -> 0.052105291
A6: 4 | B6: ='Participant 4'!E118 -> 2.6574934 | C6: ='Participant 4'!F118 -> 2.8666971 | D6: =(C6-B6)/$G$2 -> 0.041840743
A7: 5 | B7: ='Participant 5'!E108 -> 2.7841589 | C7: ='Participant 5'!F108 -> 2.9211542 | D7: =(C7-B7)/$G$2 -> 0.027399063
A8: Average Slope | D8: =AVERAGE(D3:D7) -> 0.02977431
